Workbook
Name Slicer_Category: #N/A
Name Slicer_DATE_BIN_MONTHS: #N/A
Name Slicer_Region: #N/A

Sheet Q1&Q2
A1: Order_ID | B1: Customer_ID | C1: Product_ID | D1: Order_Date | E1: Delivery_Date | F1: Customer_Name | G1: Gender | H1: DOB | I1: City | J1: Region | K1: Category | L1: Product_Name | M1: Quantity | N1: Unit_Price | O1: Discount_% | P1: Sales | Q1: Rating | R1: Payment_Mode | S1: Salesperson | T1: Email | U1: Phone | V1: Order_Status | W1: Customer_classification | X1: proper customer name | Y1: Customer_code | Z1: Standardized email-id
A2: ORD10001 | B2: C008 | C2: P202 | D2: 18/09/2025 | E2: 22/09/2025 | F2: Kavya Nair | G2: Female | H2: 01/08/1976 | I2: Hyderabad | J2: South | K2: Home Appliances | L2: Iron | M2: 4 | N2: 2200 | O2: 10 | P2: 7920 | Q2: 4 | R2: Cash | S2: Ritika | T2: KAvya.nair@company.com | U2: 9431429797 | V2: Completed | W2: {=_xlfn.IFS( OR(Q2<=2, V2="Cancelled"), "BLACKLISTED", AND(P2>=100000, Q2>=4, O2<=10, V2="Completed"), "PLATINUM", AND( P2<=99999, P2>=50000, Q2>=3, V2= "Completed"), "GOLD", AND( P2<50000, V2="Completed"), "SILVER", TRUE, "UNCLASSIFIED")} -> #NAME? | X2: =PROPER(TRIM(F2)) -> Kavya Nair | Y2: =LEFT(X2,3)&RIGHT(A2,4)&LEFT(I2,2) -> Kav0001Hy | Z2: =IF(IFERROR(FIND("@", T2), 0), TRIM(LOWER(T2)), "Invalid Email" ) -> kavya.nair@company.com
A3: ORD10002 | B3: C008 | C3: P104 | D3: 27/04/2025 | E3: 04/05/2025 | F3: Kavya Nair | G3: Female | H3: 16/10/2000 | I3: Delhi | J3: North | K3: Electronics | L3: Monitor | M3: 17 | N3: 12000 | O3: 10 | P3: 183600 | Q3: 1 | R3: NetBanking | S3: Rahul | T3: kavya.nair@company.com | U3: 9129865339 | V3: Completed | W3: {=_xlfn.IFS( OR(Q3<=2, V3="Cancelled"), "BLACKLISTED", AND(P3>=100000, Q3>=4, O3<=10, V3="Completed"), "PLATINUM", AND( P3<=99999, P3>=50000, Q3>=3, V3= "Completed"), "GOLD", AND( P3<50000, V3="Completed"), "SILVER", TRUE, "UNCLASSIFIED")} -> #NAME? | X3: =PROPER(TRIM(F3)) -> Kavya Nair | Y3: =LEFT(X3,3)&RIGHT(A3,4)&LEFT(I3,2) -> Kav0002De | Z3: =IF(IFERROR(FIND("@", T3), 0), TRIM(LOWER(T3)), "Invalid Email" ) -> kavya.nair@company.com
A4: ORD10003 | B4: C010 | C4: P101 | D4: 03/09/2025 | E4: 14/09/2025 | F4: pooja shah | G4: Female | H4: 16/09/1994 | I4: Bengaluru | J4: South | K4: Electronics | L4: Laptop | M4: 5 | N4: 55000 | O4: 5 | P4: 261250 | Q4: 3 | R4: NetBanking | S4: Aisha | T4: pooja.shah@company.com | U4: 9380975626 | V4: Pending | W4: {=_xlfn.IFS( OR(Q4<=2, V4="Cancelled"), "BLACKLISTED", AND(P4>=100000, Q4>=4, O4<=10, V4="Completed"), "PLATINUM", AND( P4<=99999, P4>=50000, Q4>=3, V4= "Completed"), "GOLD", AND( P4<50000, V4="Completed"), "SILVER", TRUE, "UNCLASSIFIED")} -> #NAME? | X4: =PROPER(TRIM(F4)) -> Pooja Shah | Y4: =LEFT(X4,3)&RIGHT(A4,4)&LEFT(I4,2) -> Poo0003Be | Z4: =IF(IFERROR(FIND("@", T4), 0), TRIM(LOWER(T4)), "Invalid Email" ) -> pooja.shah@company.com
A5: ORD10002 | B5: C008 | C5: P202 | D5: 21/03/2026 | E5: 02/04/2026 | F5: Kavya Nair | G5: Female | H5: 07/03/2004 | I5: Bengaluru | J5: South | K5: Home Appliances | L5: Iron | M5: 5 | N5: 2200 | O5: 5 | P5: 10450 | Q5: 5 | R5: NetBanking | S5: Aisha | T5: kavya.nair@company.com | U5: 9600261125 | V5: Cancelled | W5: {=_xlfn.IFS( OR(Q5<=2, V5="Cancelled"), "BLACKLISTED", AND(P5>=100000, Q5>=4, O5<=10, V5="Completed"), "PLATINUM", AND( P5<=99999, P5>=50000, Q5>=3, V5= "Completed"), "GOLD", AND( P5<50000, V5="Completed"), "SILVER", TRUE, "UNCLASSIFIED")} -> #NAME? | X5: =PROPER(TRIM(F5)) -> Kavya Nair | Y5: =LEFT(X5,3)&RIGHT(A5,4)&LEFT(I5,2) -> Kav0002Be | Z5: =IF(IFERROR(FIND("@", T5), 0), TRIM(LOWER(T5)), "Invalid Email" ) -> kavya.nair@company.com
A6: ORD10005 | B6: C009 | C6: P103 | D6: 27/09/2025 | E6: 07/10/2025 | F6: Mohit Verma | G6: Male | H6: 13/04/1976 | I6: Delhi | J6: North | K6: Electronics | L6: Keyboard | M6: 8 | N6: 1200 | O6: 5 | P6: 9120 | Q6: 2 | R6: Card | S6: Aisha | T6: mohit.verma@company.com | U6: 9724635978 | V6: Pending | W6: {=_xlfn.IFS( OR(Q6<=2, V6="Cancelled"), "BLACKLISTED", AND(P6>=100000, Q6>=4, O6<=10, V6="Completed"), "PLATINUM", AND( P6<=99999, P6>=50000, Q6>=3, V6= "Completed"), "GOLD", AND( P6<50000, V6="Completed"), "SILVER", TRUE, "UNCLASSIFIED")} -> #NAME? | X6: =PROPER(TRIM(F6)) -> Mohit Verma | Y6: =LEFT(X6,3)&RIGHT(A6,4)&LEFT(I6,2) -> Moh0005De | Z6: =IF(IFERROR(FIND("@", T6), 0), TRIM(LOWER(T6)), "Invalid Email" ) -> mohit.verma@company.com
A7: ORD10006 | B7: C007 | C7: P202 | D7: 04/01/2026 | E7: 12/01/2026 | F7: arjun Rao | G7: Male | H7: 07/02/1988 | I7: Hyderabad | J7: South | K7: Home Appliances | L7: Iron | M7: 4 | N7: 2200 | O7: 0 | P7: 8800 | Q7: 1 | R7: UPI | S7: Ritika | T7: arjun.rao@company.com | U7: 9780584905 | V7: Completed | W7: {=_xlfn.IFS( OR(Q7<=2, V7="Cancelled"), "BLACKLISTED", AND(P7>=100000, Q7>=4, O7<=10, V7="Completed"), "PLATINUM", AND( P7<=99999, P7>=50000, Q7>=3, V7= "Completed"), "GOLD", AND( P7<50000, V7="Completed"), "SILVER", TRUE, "UNCLASSIFIED")} -> #NAME? | X7: =PROPER(TRIM(F7)) -> Arjun Rao | Y7: =LEFT(X7,3)&RIGHT(A7,4)&LEFT(I7,2) -> Arj0006Hy | Z7: =IF(IFERROR(FIND("@", T7), 0), TRIM(LOWER(T7)), "Invalid Email" ) -> arjun.rao@company.com
A8: ORD10007 | B8: C008 | C8: P201 | D8: 31/02/2025 | E8: 25/02/2026 | F8: Kavya Nair | G8: Female | H8: 20/03/2003 | I8: Hyderabad | J8: South | K8: Home Appliances | L8: Mixer | M8: 2 | N8: 3500 | O8: 5 | P8: 6650 | Q8: 1 | R8: UPI | S8: Ritika | T8: kavya.nair@company.com | U8: 9958252176 | V8: Completed | W8: {=_xlfn.IFS( OR(Q8<=2, V8="Cancelled"), "BLACKLISTED", AND(P8>=100000, Q8>=4, O8<=10, V8="Completed"), "PLATINUM", AND( P8<=99999, P8>=50000, Q8>=3, V8= "Completed"), "GOLD", AND( P8<50000, V8="Completed"), "SILVER", TRUE, "UNCLASSIFIED")} -> #NAME? | X8: =PROPER(TRIM(F8)) -> Kavya Nair | Y8: =LEFT(X8,3)&RIGHT(A8,4)&LEFT(I8,2) -> Kav0007Hy | Z8: =IF(IFERROR(FIND("@", T8), 0), TRIM(LOWER(T8)), "Invalid Email" ) -> kavya.nair@company.com
A9: ORD10008 | B9: C002 | C9: P104 | D9: 13/04/2025 | E9: 19/04/2025 | F9: Priya Patel | G9: Female | H9: 07/03/1995 | I9: Mumbai | J9: West | K9: Electronics | L9: Monitor | M9: 14 | N9: 12000 | O9: 15 | P9: 142800 | Q9: 4 | R9: NetBanking | S9: Ritika | T9: priYa.patel@company.com | U9: 9705521654 | V9: Completed | W9: {=_xlfn.IFS( OR(Q9<=2, V9="Cancelled"), "BLACKLISTED", AND(P9>=100000, Q9>=4, O9<=10, V9="Completed"), "PLATINUM", AND( P9<=99999, P9>=50000, Q9>=3, V9= "Completed"), "GOLD", AND( P9<50000, V9="Completed"), "SILVER", TRUE, "UNCLASSIFIED")} -> #NAME? | X9: =PROPER(TRIM(F9)) -> Priya Patel | Y9: =LEFT(X9,3)&RIGHT(A9,4)&LEFT(I9,2) -> Pri0008Mu | Z9: =IF(IFERROR(FIND("@", T9), 0), TRIM(LOWER(T9)), "Invalid Email" ) -> priya.patel@company.com
A10: ORD10009 | B10: C008 | C10: P104 | D10: 31/01/2026 | E10: 02/02/2026 | F10: kavya Nair | G10: Female | H10: 06/04/1997 | I10: Pune | J10: West | K10: Electronics | L10: Monitor | M10: 4 | N10: 12000 | O10: 15 | P10: 40800 | Q10: 4 | R10: UPI | S10: Neha | T10: kavya.nair@company.com | U10: 9588041011 | V10: Completed | W10: {=_xlfn.IFS( OR(Q10<=2, V10="Cancelled"), "BLACKLISTED", AND(P10>=100000, Q10>=4, O10<=10, V10="Completed"), "PLATINUM", AND( P10<=99999, P10>=50000, Q10>=3, V10= "Completed"), "GOLD", AND( P10<50000, V10="Completed"), "SILVER", TRUE, "UNCLASSIFIED")} -> #NAME? | X10: =PROPER(TRIM(F10)) -> Kavya Nair | Y10: =LEFT(X10,3)&RIGHT(A10,4)&LEFT(I10,2) -> Kav0009Pu | Z10: =IF(IFERROR(FIND("@", T10), 0), TRIM(LOWER(T10)), "Invalid Email" ) -> kavya.nair@company.com
A11: ORD10010 | B11: C002 | C11: P301 | D11: 25/03/2025 | E11: 27/03/2025 | F11: Priya Patel | G11: Female | H11: 07/01/1990 | I11: Mumbai | J11: West | K11: Stationery | L11: Notebook | M11: 6 | N11: 60 | O11: 0 | P11: 360 | Q11: 4 | R11: Card | S11: Neha | T11: PRiya.patel@company.com | U11: 9340540608 | V11: Completed | W11: {=_xlfn.IFS( OR(Q11<=2, V11="Cancelled"), "BLACKLISTED", AND(P11>=100000, Q11>=4, O11<=10, V11="Completed"), "PLATINUM", AND( P11<=99999, P11>=50000, Q11>=3, V11= "Completed"), "GOLD", AND( P11<50000, V11="Completed"), "SILVER", TRUE, "UNCLASSIFIED")} -> #NAME? | X11: =PROPER(TRIM(F11)) -> Priya Patel | Y11: =LEFT(X11,3)&RIGHT(A11,4)&LEFT(I11,2) -> Pri0010Mu | Z11: =IF(IFERROR(FIND("@", T11), 0), TRIM(LOWER(T11)), "Invalid Email" ) -> priya.patel@company.com
A12: ORD10011 | B12: C003 | C12: P202 | D12: 19/09/2025 | E12: 23/09/2025 | F12: Rohit Singh | G12: Male | H12: 10/05/1982 | I12: Delhi | J12: North | K12: Home Appliances | L12: Iron | M12: -3 | N12: 2200 | O12: 0 | P12: 35200 | Q12: 2 | R12: Card | S12: Rahul | T12: rohit.singh@company.com | U12: 9521710321 | V12: Pending | W12: {=_xlfn.IFS( OR(Q12<=2, V12="Cancelled"), "BLACKLISTED", AND(P12>=100000, Q12>=4, O12<=10, V12="Completed"), "PLATINUM", AND( P12<=99999, P12>=50000, Q12>=3, V12= "Completed"), "GOLD", AND( P12<50000, V12="Completed"), "SILVER", TRUE, "UNCLASSIFIED")} -> #NAME? | X12: =PROPER(TRIM(F12)) -> Rohit Singh | Y12: =LEFT(X12,3)&RIGHT(A12,4)&LEFT(I12,2) -> Roh0011De | Z12: =IF(IFERROR(FIND("@", T12), 0), TRIM(LOWER(T12)), "Invalid Email" ) -> rohit.singh@company.com
A13: ORD10012 | B13: C008 | C13: P201 | D13: 08/03/2025 | E13: 15/03/2025 | F13: Kavya Nair | G13: Female | H13: 23/01/1982 | I13: Ahmedabad | J13: West | K13: Home Appliances | L13: Mixer | M13: 10 | N13: 3500 | O13: 5 | P13: 33250 | Q13: 5 | R13: Card | S13: Aisha | T13: kavya.nair@company.com | U13: 9123535241 | V13: Cancelled | W13: {=_xlfn.IFS( OR(Q13<=2, V13="Cancelled"), "BLACKLISTED", AND(P13>=100000, Q13>=4, O13<=10, V13="Completed"), "PLATINUM", AND( P13<=99999, P13>=50000, Q13>=3, V13= "Completed"), "GOLD", AND( P13<50000, V13="Completed"), "SILVER", TRUE, "UNCLASSIFIED")} -> #NAME? | X13: =PROPER(TRIM(F13)) -> Kavya Nair | Y13: =LEFT(X13,3)&RIGHT(A13,4)&LEFT(I13,2) -> Kav0012Ah | Z13: =IF(IFERROR(FIND("@", T13), 0), TRIM(LOWER(T13)), "Invalid Email" ) -> kavya.nair@company.com
... A39: ORD10038 | B39: C006 | C39: P201 | D39: 08/03/2026 | E39: 20/03/2026 | F39: Sneha Joshi | G39: Female | H39: 21/06/1980 | I39: Delhi | J39: North | K39: Home Appliances | L39: Mixer | M39: 20 | N39: 3500 | O39: 10 | P39: 63000 | Q39: 3 | R39: Card | S39: Rahul | T39: sneha.joshi@company.com | U39: 9283578533 | V39: Cancelled | W39: {=_xlfn.IFS( OR(Q39<=2, V39="Cancelled"), "BLACKLISTED", AND(P39>=100000, Q39>=4, O39<=10, V39="Completed"), "PLATINUM", AND( P39<=99999, P39>=50000, Q39>=3, V39= "Completed"), "GOLD", AND( P39<50000, V39="Completed"), "SILVER", TRUE, "UNCLASSIFIED")} -> #NAME? | X39: =PROPER(TRIM(F39)) -> Sneha Joshi | Y39: =LEFT(X39,3)&RIGHT(A39,4)&LEFT(I39,2) -> Sne0038De | Z39: =IF(IFERROR(FIND("@", T39), 0), TRIM(LOWER(T39)), "Invalid Email" ) -> sneha.joshi@company.com
A40: ORD10039 | B40: C008 | C40: P302 | D40: 13/02/2025 | E40: 19/02/2025 | F40: Kavya Nair | G40: Female | H40: 17/06/1979 | I40: Pune | J40: West | K40: Stationery | L40: Pen | M40: 5 | N40: 1200 | O40: 0 | P40: 100 | Q40: 1 | R40: Cash | S40: Rahul | T40: kavya.nair@company.com | U40: 9963005771 | V40: Cancelled | W40: {=_xlfn.IFS( OR(Q40<=2, V40="Cancelled"), "BLACKLISTED", AND(P40>=100000, Q40>=4, O40<=10, V40="Completed"), "PLATINUM", AND( P40<=99999, P40>=50000, Q40>=3, V40= "Completed"), "GOLD", AND( P40<50000, V40="Completed"), "SILVER", TRUE, "UNCLASSIFIED")} -> #NAME? | X40: =PROPER(TRIM(F40)) -> Kavya Nair | Y40: =LEFT(X40,3)&RIGHT(A40,4)&LEFT(I40,2) -> Kav0039Pu | Z40: =IF(IFERROR(FIND("@", T40), 0), TRIM(LOWER(T40)), "Invalid Email" ) -> kavya.nair@company.com
A41: ORD10040 | B41: C010 | C41: P203 | D41: 05/10/2025 | E41: 15/10/2025 | F41: Pooja Shah | G41: Female | H41: 18/06/1992 | I41: Mumbai | J41: West | K41: Home Appliances | L41: Microwave | M41: 20 | N41: 8500 | O41: 0 | P41: 170000 | Q41: 1 | R41: UPI | S41: Neha | T41: pooja.shah@company.com | U41: 9484632635 | V41: Cancelled | W41: {=_xlfn.IFS( OR(Q41<=2, V41="Cancelled"), "BLACKLISTED", AND(P41>=100000, Q41>=4, O41<=10, V41="Completed"), "PLATINUM", AND( P41<=99999, P41>=50000, Q41>=3, V41= "Completed"), "GOLD", AND( P41<50000, V41="Completed"), "SILVER", TRUE, "UNCLASSIFIED")} -> #NAME? | X41: =PROPER(TRIM(F41)) -> Pooja Shah | Y41: =LEFT(X41,3)&RIGHT(A41,4)&LEFT(I41,2) -> Poo0040Mu | Z41: =IF(IFERROR(FIND("@", T41), 0), TRIM(LOWER(T41)), "Invalid Email" ) -> pooja.shah@company.com
A42: ORD10041 | B42: C007 | C42: P301 | D42: 10/02/2026 | E42: 12/02/2026 | F42: Arjun Rao | G42: Male | H42: 06/06/1994 | I42: Bengaluru | J42: South | K42: Stationery | L42: Notebook | M42: 8 | N42: 60 | O42: 15 | P42: 408 | Q42: 5 | R42: UPI | S42: Rahul | T42: arjun.rao@company.com | U42: 9276319484 | V42: Pending | W42: {=_xlfn.IFS( OR(Q42<=2, V42="Cancelled"), "BLACKLISTED", AND(P42>=100000, Q42>=4, O42<=10, V42="Completed"), "PLATINUM", AND( P42<=99999, P42>=50000, Q42>=3, V42= "Completed"), "GOLD", AND( P42<50000, V42="Completed"), "SILVER", TRUE, "UNCLASSIFIED")} -> #NAME? | X42: =PROPER(TRIM(F42)) -> Arjun Rao | Y42: =LEFT(X42,3)&RIGHT(A42,4)&LEFT(I42,2) -> Arj0041Be | Z42: =IF(IFERROR(FIND("@", T42), 0), TRIM(LOWER(T42)), "Invalid Email" ) -> arjun.rao@company.com
A43: ORD10042 | B43: C010 | C43: P201 | D43: 04/06/2025 | E43: 16/06/2025 | F43: Pooja Shah | G43: Female | H43: 22/09/1988 | I43: Pune | J43: West | K43: Home Appliances | L43: Mixer | M43: 8 | N43: 3500 | O43: 5 | P43: 26600 | Q43: 1 | R43: Card | S43: Neha | T43: pooja.shah@company.com | U43: 9619034852 | V43: Pending | W43: {=_xlfn.IFS( OR(Q43<=2, V43="Cancelled"), "BLACKLISTED", AND(P43>=100000, Q43>=4, O43<=10, V43="Completed"), "PLATINUM", AND( P43<=99999, P43>=50000, Q43>=3, V43= "Completed"), "GOLD", AND( P43<50000, V43="Completed"), "SILVER", TRUE, "UNCLASSIFIED")} -> #NAME? | X43: =PROPER(TRIM(F43)) -> Pooja Shah | Y43: =LEFT(X43,3)&RIGHT(A43,4)&LEFT(I43,2) -> Poo0042Pu | Z43: =IF(IFERROR(FIND("@", T43), 0), TRIM(LOWER(T43)), "Invalid Email" ) -> pooja.shah@company.com
A44: ORD10043 | B44: C009 | C44: P203 | D44: 08/02/2026 | E44: 14/02/2026 | F44: Mohit Verma | G44: Male | H44: 14/07/2001 | I44: Jaipur | J44: North | K44: Home Appliances | L44: Microwave | M44: 1 | N44: 8500 | O44: 0 | P44: 8500 | Q44: 2 | R44: Card | S44: Neha | T44: mohit.verma@company.com | U44: 9636416962 | V44: Pending | W44: {=_xlfn.IFS( OR(Q44<=2, V44="Cancelled"), "BLACKLISTED", AND(P44>=100000, Q44>=4, O44<=10, V44="Completed"), "PLATINUM", AND( P44<=99999, P44>=50000, Q44>=3, V44= "Completed"), "GOLD", AND( P44<50000, V44="Completed"), "SILVER", TRUE, "UNCLASSIFIED")} -> #NAME? | X44: =PROPER(TRIM(F44)) -> Mohit Verma | Y44: =LEFT(X44,3)&RIGHT(A44,4)&LEFT(I44,2) -> Moh0043Ja | Z44: =IF(IFERROR(FIND("@", T44), 0), TRIM(LOWER(T44)), "Invalid Email" ) -> mohit.verma@company.com
A45: ORD10044 | B45: C001 | C45: P303 | D45: 30/03/2025 | E45: 31/03/2025 | F45: amit Sharma | G45: Male | H45: 09/08/1991 | I45: Pune | J45: West | K45: Stationery | L45: Marker | M45: 8 | N45: 45 | O45: 15 | P45: 306 | Q45: 2 | R45: Card | S45: Aisha | T45: amit.sharma@company.com | U45: 9357133880 | V45: Completed | W45: {=_xlfn.IFS( OR(Q45<=2, V45="Cancelled"), "BLACKLISTED", AND(P45>=100000, Q45>=4, O45<=10, V45="Completed"), "PLATINUM", AND( P45<=99999, P45>=50000, Q45>=3, V45= "Completed"), "GOLD", AND( P45<50000, V45="Completed"), "SILVER", TRUE, "UNCLASSIFIED")} -> #NAME? | X45: =PROPER(TRIM(F45)) -> Amit Sharma | Y45: =LEFT(X45,3)&RIGHT(A45,4)&LEFT(I45,2) -> Ami0044Pu | Z45: =IF(IFERROR(FIND("@", T45), 0), TRIM(LOWER(T45)), "Invalid Email" ) -> amit.sharma@company.com
A46: ORD10045 | B46: C006 | C46: P202 | D46: 25/04/2025 | E46: 28/04/2025 | F46: Sneha Joshi | G46: Female | H46: 21/10/1988 | I46: Pune | J46: West | K46: Home Appliances | L46: Iron | M46: 16 | N46: 2200 | O46: 5 | P46: 33440 | Q46: 5 | R46: Card | S46: Aisha | T46: sneha.joshi@company.com | U46: 9575210324 | V46: Cancelled | W46: {=_xlfn.IFS( OR(Q46<=2, V46="Cancelled"), "BLACKLISTED", AND(P46>=100000, Q46>=4, O46<=10, V46="Completed"), "PLATINUM", AND( P46<=99999, P46>=50000, Q46>=3, V46= "Completed"), "GOLD", AND( P46<50000, V46="Completed"), "SILVER", TRUE, "UNCLASSIFIED")} -> #NAME? | X46: =PROPER(TRIM(F46)) -> Sneha Joshi | Y46: =LEFT(X46,3)&RIGHT(A46,4)&LEFT(I46,2) -> Sne0045Pu | Z46: =IF(IFERROR(FIND("@", T46), 0), TRIM(LOWER(T46)), "Invalid Email" ) -> sneha.joshi@company.com
A47: ORD10046 | B47: C009 | C47: P201 | D47: 13/10/2025 | E47: 23/10/2025 | F47: Mohit Verma | G47: Male | H47: 19/11/2002 | I47: Bengaluru | J47: South | K47: Home Appliances | L47: Mixer | M47: 19 | N47: 3500 | O47: 20 | P47: 53200 | Q47: 3 | R47: Cash | S47: Karan | T47: mohit.verma@company.com | U47: 9276080204 | V47: Cancelled | W47: {=_xlfn.IFS( OR(Q47<=2, V47="Cancelled"), "BLACKLISTED", AND(P47>=100000, Q47>=4, O47<=10, V47="Completed"), "PLATINUM", AND( P47<=99999, P47>=50000, Q47>=3, V47= "Completed"), "GOLD", AND( P47<50000, V47="Completed"), "SILVER", TRUE, "UNCLASSIFIED")} -> #NAME? | X47: =PROPER(TRIM(F47)) -> Mohit Verma | Y47: =LEFT(X47,3)&RIGHT(A47,4)&LEFT(I47,2) -> Moh0046Be | Z47: =IF(IFERROR(FIND("@", T47), 0), TRIM(LOWER(T47)), "Invalid Email" ) -> mohit.verma@company.com
A48: ORD10047 | B48: C006 | C48: P102 | D48: 11/10/2025 | E48: 14/10/2025 | F48: Sneha Joshi | G48: Female | H48: 06/07/2000 | I48: Pune | J48: West | K48: Electronics | L48: Mouse | M48: 15 | N48: 700 | O48: 15 | P48: 8925 | Q48: 4 | R48: UPI | S48: Neha | T48: sneha.joshicompany.com | U48: 9856624471 | V48: Completed | W48: {=_xlfn.IFS( OR(Q48<=2, V48="Cancelled"), "BLACKLISTED", AND(P48>=100000, Q48>=4, O48<=10, V48="Completed"), "PLATINUM", AND( P48<=99999, P48>=50000, Q48>=3, V48= "Completed"), "GOLD", AND( P48<50000, V48="Completed"), "SILVER", TRUE, "UNCLASSIFIED")} -> #NAME? | X48: =PROPER(TRIM(F48)) -> Sneha Joshi | Y48: =LEFT(X48,3)&RIGHT(A48,4)&LEFT(I48,2) -> Sne0047Pu | Z48: =IF(IFERROR(FIND("@", T48), 0), TRIM(LOWER(T48)), "Invalid Email" ) -> Invalid Email
A49: ORD10048 | B49: C006 | C49: P102 | D49: 27/11/2025 | E49: 03/12/2025 | F49: Sneha Joshi | G49: Female | H49: 26/11/1998 | I49: Jaipur | J49: North | K49: Electronics | L49: Mouse | M49: 19 | N49: 700 | O49: 20 | P49: 10640 | Q49: 1 | R49: Cash | S49: Neha | T49: sneha.joshi@company.com | U49: 9238141322 | V49: Completed | W49: {=_xlfn.IFS( OR(Q49<=2, V49="Cancelled"), "BLACKLISTED", AND(P49>=100000, Q49>=4, O49<=10, V49="Completed"), "PLATINUM", AND( P49<=99999, P49>=50000, Q49>=3, V49= "Completed"), "GOLD", AND( P49<50000, V49="Completed"), "SILVER", TRUE, "UNCLASSIFIED")} -> #NAME? | X49: =PROPER(TRIM(F49)) -> Sneha Joshi | Y49: =LEFT(X49,3)&RIGHT(A49,4)&LEFT(I49,2) -> Sne0048Ja | Z49: =IF(IFERROR(FIND("@", T49), 0), TRIM(LOWER(T49)), "Invalid Email" ) -> sneha.joshi@company.com
A50: ORD10049 | B50: C009 | C50: P104 | D50: 19/04/2026 | F50: Mohit Verma | G50: Male | H50: 03/06/1996 | I50: Delhi | J50: North | K50: Electronics | L50: Monitor | M50: 19 | N50: 12000 | O50: 0 | P50: 228000 | Q50: 1 | R50: NetBanking | S50: Aisha | T50: mohit.verma@company.com | U50: 9890380030 | V50: Completed | W50: {=_xlfn.IFS( OR(Q50<=2, V50="Cancelled"), "BLACKLISTED", AND(P50>=100000, Q50>=4, O50<=10, V50="Completed"), "PLATINUM", AND( P50<=99999, P50>=50000, Q50>=3, V50= "Completed"), "GOLD", AND( P50<50000, V50="Completed"), "SILVER", TRUE, "UNCLASSIFIED")} -> #NAME? | X50: =PROPER(TRIM(F50)) -> Mohit Verma | Y50: =LEFT(X50,3)&RIGHT(A50,4)&LEFT(I50,2) -> Moh0049De | Z50: =IF(IFERROR(FIND("@", T50), 0), TRIM(LOWER(T50)), "Invalid Email" ) -> mohit.verma@company.com
A51: ORD10050 | B51: C004 | C51: P103 | D51: 19/04/2026 | E51: 21/04/2026 | F51: Anita Gupta | G51: Female | H51: 15/03/1987 | I51: Pune | J51: West | K51: Electronics | L51: Keyboard | M51: 6 | N51: 1200 | O51: 5 | P51: 6840 | Q51: 2 | R51: Cash | S51: Ritika | T51: anita.gupta@company.com | U51: 9495893170 | V51: Pending | W51: {=_xlfn.IFS( OR(Q51<=2, V51="Cancelled"), "BLACKLISTED", AND(P51>=100000, Q51>=4, O51<=10, V51="Completed"), "PLATINUM", AND( P51<=99999, P51>=50000, Q51>=3, V51= "Completed"), "GOLD", AND( P51<50000, V51="Completed"), "SILVER", TRUE, "UNCLASSIFIED")} -> #NAME? | X51: =PROPER(TRIM(F51)) -> Anita Gupta | Y51: =LEFT(X51,3)&RIGHT(A51,4)&LEFT(I51,2) -> Ani0050Pu | Z51: =IF(IFERROR(FIND("@", T51), 0), TRIM(LOWER(T51)), "Invalid Email" ) -> anita.gupta@company.com
A52: ORD10051 | B52: C010 | C52: P202 | D52: 28/03/2025 | E52: 07/04/2025 | F52: POoja Shah | G52: Female | H52: 20/02/1979 | I52: Bengaluru | J52: South | K52: Home Appliances | L52: Iron | M52: 7 | N52: 2200 | O52: 15 | P52: 13090 | Q52: 1 | R52: UPI | S52: Aisha | T52: pooja.shah@company.com | U52: 9485166307 | V52: Completed | W52: {=_xlfn.IFS( OR(Q52<=2, V52="Cancelled"), "BLACKLISTED", AND(P52>=100000, Q52>=4, O52<=10, V52="Completed"), "PLATINUM", AND( P52<=99999, P52>=50000, Q52>=3, V52= "Completed"), "GOLD", AND( P52<50000, V52="Completed"), "SILVER", TRUE, "UNCLASSIFIED")} -> #NAME? | X52: =PROPER(TRIM(F52)) -> Pooja Shah | Y52: =LEFT(X52,3)&RIGHT(A52,4)&LEFT(I52,2) -> Poo0051Be | Z52: =IF(IFERROR(FIND("@", T52), 0), TRIM(LOWER(T52)), "Invalid Email" ) -> pooja.shah@company.com
A53: ORD10052 | B53: C002 | C53: P301 | D53: 25/08/2025 | E53: 28/08/2025 | F53: Priya Patel | G53: Female | H53: 09/08/2000 | I53: Jaipur | J53: North | K53: Stationery | L53: Notebook | M53: 8 | N53: 60 | O53: 10 | P53: 432 | Q53: 5 | R53: Card | S53: Aisha | T53: priya.patel@company.com | U53: 9924709648 | V53: Cancelled | W53: {=_xlfn.IFS( OR(Q53<=2, V53="Cancelled"), "BLACKLISTED", AND(P53>=100000, Q53>=4, O53<=10, V53="Completed"), "PLATINUM", AND( P53<=99999, P53>=50000, Q53>=3, V53= "Completed"), "GOLD", AND( P53<50000, V53="Completed"), "SILVER", TRUE, "UNCLASSIFIED")} -> #NAME? | X53: =PROPER(TRIM(F53)) -> Priya Patel | Y53: =LEFT(X53,3)&RIGHT(A53,4)&LEFT(I53,2) -> Pri0052Ja | Z53: =IF(IFERROR(FIND("@", T53), 0), TRIM(LOWER(T53)), "Invalid Email" ) -> priya.patel@company.com
A54: ORD10053 | B54: C005 | C54: P101 | D54: 19/08/2025 | E54: 23/08/2025 | F54: Vikas Mehta | G54: Male | H54: 17/01/1976 | I54: Kolkata | J54: East | K54: Electronics | L54: Laptop | M54: 12 | N54: 55000 | O54: 5 | P54: 627000 | Q54: 2 | R54: UPI | S54: Rahul | T54: vikas.mehta@company.com | U54: 9350554626 | V54: Pending | W54: {=_xlfn.IFS( OR(Q54<=2, V54="Cancelled"), "BLACKLISTED", AND(P54>=100000, Q54>=4, O54<=10, V54="Completed"), "PLATINUM", AND( P54<=99999, P54>=50000, Q54>=3, V54= "Completed"), "GOLD", AND( P54<50000, V54="Completed"), "SILVER", TRUE, "UNCLASSIFIED")} -> #NAME? | X54: =PROPER(TRIM(F54)) -> Vikas Mehta | Y54: =LEFT(X54,3)&RIGHT(A54,4)&LEFT(I54,2) -> Vik0053Ko | Z54: =IF(IFERROR(FIND("@", T54), 0), TRIM(LOWER(T54)), "Invalid Email" ) -> vikas.mehta@company.com
A55: ORD10054 | B55: C008 | C55: P102 | D55: 27/07/2025 | E55: 05/08/2025 | F55: Kavya Nair | G55: Female | H55: 04/04/1975 | I55: Jaipur | J55: North | K55: Electronics | L55: Mouse | M55: 3 | N55: 700 | O55: 0 | P55: 2100 | Q55: 3 | R55: Card | S55: Karan | T55: kavya.nair@company.com | U55: 9743295580 | V55: Cancelled | W55: {=_xlfn.IFS( OR(Q55<=2, V55="Cancelled"), "BLACKLISTED", AND(P55>=100000, Q55>=4, O55<=10, V55="Completed"), "PLATINUM", AND( P55<=99999, P55>=50000, Q55>=3, V55= "Completed"), "GOLD", AND( P55<50000, V55="Completed"), "SILVER", TRUE, "UNCLASSIFIED")} -> #NAME? | X55: =PROPER(TRIM(F55)) -> Kavya Nair | Y55: =LEFT(X55,3)&RIGHT(A55,4)&LEFT(I55,2) -> Kav0054Ja | Z55: =IF(IFERROR(FIND("@", T55), 0), TRIM(LOWER(T55)), "Invalid Email" ) -> kavya.nair@company.com
A56: ORD10055 | B56: C003 | C56: P301 | D56: 21/02/2025 | E56: 26/02/2025 | F56: RoHit Singh | G56: Male | H56: 11/12/1976 | I56: Ahmedabad | J56: West | K56: Stationery | L56: Notebook | M56: 19 | N56: 60 | O56: 15 | P56: 969 | Q56: 4 | R56: Card | S56: Rahul | T56: rohit.singh@company.com | U56: 9822926495 | V56: Cancelled | W56: {=_xlfn.IFS( OR(Q56<=2, V56="Cancelled"), "BLACKLISTED", AND(P56>=100000, Q56>=4, O56<=10, V56="Completed"), "PLATINUM", AND( P56<=99999, P56>=50000, Q56>=3, V56= "Completed"), "GOLD", AND( P56<50000, V56="Completed"), "SILVER", TRUE, "UNCLASSIFIED")} -> #NAME? | X56: =PROPER(TRIM(F56)) -> Rohit Singh | Y56: =LEFT(X56,3)&RIGHT(A56,4)&LEFT(I56,2) -> Roh0055Ah | Z56: =IF(IFERROR(FIND("@", T56), 0), TRIM(LOWER(T56)), "Invalid Email" ) -> rohit.singh@company.com
A57: ORD10056 | B57: C001 | C57: P301 | D57: 10/08/2025 | E57: 11/08/2025 | F57: Amit Sharma | G57: Male | H57: 03/12/1979 | I57: Jaipur | J57: North | K57: Stationery | L57: Notebook | M57: 9 | N57: 60 | O57: 20 | P57: 432 | Q57: 1 | R57: NetBanking | S57: Neha | T57: amit.sharma@company.com | U57: 9518298190 | V57: Pending | W57: {=_xlfn.IFS( OR(Q57<=2, V57="Cancelled"), "BLACKLISTED", AND(P57>=100000, Q57>=4, O57<=10, V57="Completed"), "PLATINUM", AND( P57<=99999, P57>=50000, Q57>=3, V57= "Completed"), "GOLD", AND( P57<50000, V57="Completed"), "SILVER", TRUE, "UNCLASSIFIED")} -> #NAME? | X57: =PROPER(TRIM(F57)) -> Amit Sharma | Y57: =LEFT(X57,3)&RIGHT(A57,4)&LEFT(I57,2) -> Ami0056Ja | Z57: =IF(IFERROR(FIND("@", T57), 0), TRIM(LOWER(T57)), "Invalid Email" ) -> amit.sharma@company.com
A58: ORD10057 | B58: C001 | C58: P102 | D58: 24/03/2026 | E58: 30/03/2026 | F58: Amit Sharma | G58: Male | H58: 27/12/1978 | I58: Bengaluru | J58: South | K58: Electronics | L58: Mouse | M58: 6 | N58: 700 | O58: 0 | P58: 4200 | Q58: 4 | R58: UPI | S58: Rahul | T58: amit.sharmcompany.com | U58: 9366223547 | V58: Cancelled | W58: {=_xlfn.IFS( OR(Q58<=2, V58="Cancelled"), "BLACKLISTED", AND(P58>=100000, Q58>=4, O58<=10, V58="Completed"), "PLATINUM", AND( P58<=99999, P58>=50000, Q58>=3, V58= "Completed"), "GOLD", AND( P58<50000, V58="Completed"), "SILVER", TRUE, "UNCLASSIFIED")} -> #NAME? | X58: =PROPER(TRIM(F58)) -> Amit Sharma | Y58: =LEFT(X58,3)&RIGHT(A58,4)&LEFT(I58,2) -> Ami0057Be | Z58: =IF(IFERROR(FIND("@", T58), 0), TRIM(LOWER(T58)), "Invalid Email" ) -> Invalid Email
A59: ORD10058 | B59: C003 | C59: P303 | D59: 13/03/2026 | E59: 19/03/2026 | F59: Rohit Singh | G59: Male | H59: 15/04/1975 | I59: Delhi | J59: North | K59: Stationery | L59: Marker | M59: 18 | N59: 45 | O59: 5 | P59: 769.5 | Q59: 1 | R59: Card | S59: Aisha | T59: rohit.singh@company.com | U59: 9701988524 | V59: Pending | W59: {=_xlfn.IFS( OR(Q59<=2, V59="Cancelled"), "BLACKLISTED", AND(P59>=100000, Q59>=4, O59<=10, V59="Completed"), "PLATINUM", AND( P59<=99999, P59>=50000, Q59>=3, V59= "Completed"), "GOLD", AND( P59<50000, V59="Completed"), "SILVER", TRUE, "UNCLASSIFIED")} -> #NAME? | X59: =PROPER(TRIM(F59)) -> Rohit Singh | Y59: =LEFT(X59,3)&RIGHT(A59,4)&LEFT(I59,2) -> Roh0058De | Z59: =IF(IFERROR(FIND("@", T59), 0), TRIM(LOWER(T59)), "Invalid Email" ) -> rohit.singh@company.com
A60: ORD10059 | B60: C007 | C60: P302 | D60: 15/06/2025 | E60: 26/06/2025 | F60: Arjun Rao | G60: Male | H60: 19/12/1988 | I60: Jaipur | J60: North | K60: Stationery | L60: Pen | M60: 8 | N60: 20 | O60: 5 | P60: 152 | Q60: 1 | R60: Card | S60: Ritika | T60: arjun.rao@company.com | U60: 9836327649 | V60: completed | W60: {=_xlfn.IFS( OR(Q60<=2, V60="Cancelled"), "BLACKLISTED", AND(P60>=100000, Q60>=4, O60<=10, V60="Completed"), "PLATINUM", AND( P60<=99999, P60>=50000, Q60>=3, V60= "Completed"), "GOLD", AND( P60<50000, V60="Completed"), "SILVER", TRUE, "UNCLASSIFIED")} -> #NAME? | X60: =PROPER(TRIM(F60)) -> Arjun Rao | Y60: =LEFT(X60,3)&RIGHT(A60,4)&LEFT(I60,2) -> Arj0059Ja | Z60: =IF(IFERROR(FIND("@", T60), 0), TRIM(LOWER(T60)), "Invalid Email" ) -> arjun.rao@company.com
A61: ORD10060 | B61: C005 | C61: P102 | D61: 05/03/2025 | E61: 06/03/2025 | F61: Vikas Mehta | G61: Male | H61: 07/03/1979 | I61: Jaipur | J61: North | K61: Electronics | L61: Mouse | M61: 8 | N61: 700 | O61: 10 | P61: 5040 | Q61: 1 | R61: NetBanking | S61: Aisha | T61: Vikas.mehta@company.com | U61: 9261800516 | V61: Cancelled | W61: {=_xlfn.IFS( OR(Q61<=2, V61="Cancelled"), "BLACKLISTED", AND(P61>=100000, Q61>=4, O61<=10, V61="Completed"), "PLATINUM", AND( P61<=99999, P61>=50000, Q61>=3, V61= "Completed"), "GOLD", AND( P61<50000, V61="Completed"), "SILVER", TRUE, "UNCLASSIFIED")} -> #NAME? | X61: =PROPER(TRIM(F61)) -> Vikas Mehta | Y61: =LEFT(X61,3)&RIGHT(A61,4)&LEFT(I61,2) -> Vik0060Ja | Z61: =IF(IFERROR(FIND("@", T61), 0), TRIM(LOWER(T61)), "Invalid Email" ) -> vikas.mehta@company.com
A62: ORD10061 | B62: C008 | C62: P302 | D62: 09/04/2026 | E62: 19/04/2026 | F62: Kavya Nair | G62: Female | H62: 17/12/2003 | I62: Delhi | J62: North | K62: Stationery | L62: Pen | M62: 7 | N62: 20 | O62: 15 | P62: 119 | Q62: 5 | R62: Card | S62: Rahul | T62: kavya.nair@company.com | U62: 9950802015 | V62: Completed | W62: {=_xlfn.IFS( OR(Q62<=2, V62="Cancelled"), "BLACKLISTED", AND(P62>=100000, Q62>=4, O62<=10, V62="Completed"), "PLATINUM", AND( P62<=99999, P62>=50000, Q62>=3, V62= "Completed"), "GOLD", AND( P62<50000, V62="Completed"), "SILVER", TRUE, "UNCLASSIFIED")} -> #NAME? | X62: =PROPER(TRIM(F62)) -> Kavya Nair | Y62: =LEFT(X62,3)&RIGHT(A62,4)&LEFT(I62,2) -> Kav0061De | Z62: =IF(IFERROR(FIND("@", T62), 0), TRIM(LOWER(T62)), "Invalid Email" ) -> kavya.nair@company.com
... A74: ORD10073 | B74: C008 | C74: P103 | D74: 13/12/2025 | E74: 23/12/2025 | F74: Kavya Nair | G74: Female | H74: 22/09/1981 | I74: Jaipur | J74: North | K74: Electronics | L74: Keyboard | M74: 1 | N74: 1200 | O74: 5 | P74: 1140 | Q74: 3 | R74: UPI | S74: Aisha | T74: kavya.nair@company.com | U74: 9808988530 | V74: Cancelled | W74: {=_xlfn.IFS( OR(Q74<=2, V74="Cancelled"), "BLACKLISTED", AND(P74>=100000, Q74>=4, O74<=10, V74="Completed"), "PLATINUM", AND( P74<=99999, P74>=50000, Q74>=3, V74= "Completed"), "GOLD", AND( P74<50000, V74="Completed"), "SILVER", TRUE, "UNCLASSIFIED")} -> #NAME? | X74: =PROPER(TRIM(F74)) -> Kavya Nair | Y74: =LEFT(X74,3)&RIGHT(A74,4)&LEFT(I74,2) -> Kav0073Ja | Z74: =IF(IFERROR(FIND("@", T74), 0), TRIM(LOWER(T74)), "Invalid Email" ) -> kavya.nair@company.com
A75: ORD10074 | B75: C010 | C75: P202 | D75: 04/02/2026 | E75: 16/02/2026 | F75: Pooja Shah | G75: Female | H75: 20/06/1980 | J75: South | K75: Home Appliances | L75: Iron | M75: 1 | N75: 2200 | O75: 15 | P75: 1870 | Q75: 4 | R75: Card | S75: Aisha | T75: pooja.shah@company.com | U75: 9286410494 | V75: Completed | W75: {=_xlfn.IFS( OR(Q75<=2, V75="Cancelled"), "BLACKLISTED", AND(P75>=100000, Q75>=4, O75<=10, V75="Completed"), "PLATINUM", AND( P75<=99999, P75>=50000, Q75>=3, V75= "Completed"), "GOLD", AND( P75<50000, V75="Completed"), "SILVER", TRUE, "UNCLASSIFIED")} -> #NAME? | X75: =PROPER(TRIM(F75)) -> Pooja Shah | Y75: =LEFT(X75,3)&RIGHT(A75,4)&LEFT(I75,2) -> Poo0074 | Z75: =IF(IFERROR(FIND("@", T75), 0), TRIM(LOWER(T75)), "Invalid Email" ) -> pooja.shah@company.com
A76: ORD10075 | B76: C003 | C76: P103 | D76: 26/01/2026 | E76: 28/01/2026 | F76: Rohit Singh | G76: Male | H76: 02/11/1982 | I76: Pune | J76: West | K76: Electronics | L76: Keyboard | M76: 3 | N76: 1200 | O76: 10 | P76: 3240 | Q76: 5 | R76: Cash | S76: Rahul | T76: rohit.singh@company.com | U76: 9311555196 | V76: Completed | W76: {=_xlfn.IFS( OR(Q76<=2, V76="Cancelled"), "BLACKLISTED", AND(P76>=100000, Q76>=4, O76<=10, V76="Completed"), "PLATINUM", AND( P76<=99999, P76>=50000, Q76>=3, V76= "Completed"), "GOLD", AND( P76<50000, V76="Completed"), "SILVER", TRUE, "UNCLASSIFIED")} -> #NAME? | X76: =PROPER(TRIM(F76)) -> Rohit Singh | Y76: =LEFT(X76,3)&RIGHT(A76,4)&LEFT(I76,2) -> Roh0075Pu | Z76: =IF(IFERROR(FIND("@", T76), 0), TRIM(LOWER(T76)), "Invalid Email" ) -> rohit.singh@company.com
...

Sheet Q3
A1: Order_ID | B1: Customer_ID | C1: Product_ID | D1: Order_Date | E1: Delivery_Date | F1: Customer_Name | G1: Gender | H1: DOB | I1: City | J1: Region | K1: Category | L1: Product_Name | M1: Quantity | N1: Unit_Price | O1: Discount_% | P1: Sales | Q1: Rating | R1: Payment_Mode | S1: Salesperson | T1: Email | U1: Phone | V1: Order_Status | W1: proper customer name | X1: Customer Age | Y1: Delivery time(D) | Z1: Delivery status
A2: ORD10001 | B2: C008 | C2: P202 | D2: 18/09/2025 | E2: 22/09/2025 | F2: Kavya Nair | G2: Female | H2: 01/08/1976 | I2: Hyderabad | J2: South | K2: Home Appliances | L2: Iron | M2: 4 | N2: 2200 | O2: 10 | P2: 7920 | Q2: 4 | R2: Cash | S2: Ritika | T2: KAvya.nair@company.com | U2: 9431429797 | V2: Completed | W2: =PROPER(TRIM(F2)) -> Kavya Nair | X2: =IFERROR(DATEDIF(H2, TODAY(), "y"), " ") -> 49 | Y2: =IFERROR(DATEDIF(D2, E2, "D"), " ") -> 4 | Z2: {=_xlfn.IFS(Y2<=5, "On time", AND(Y2>5, Y2<>" "), "Delayed", Y2=" ", "pending" )} -> #NAME?
A3: ORD10002 | B3: C008 | C3: P104 | D3: 27/04/2025 | E3: 04/05/2025 | F3: Kavya Nair | G3: Female | H3: 16/10/2000 | I3: Delhi | J3: North | K3: Electronics | L3: Monitor | M3: 17 | N3: 12000 | O3: 10 | P3: 183600 | Q3: 1 | R3: NetBanking | S3: Rahul | T3: kavya.nair@company.com | U3: 9129865339 | V3: Completed | W3: =PROPER(TRIM(F3)) -> Kavya Nair | X3: =IFERROR(DATEDIF(H3, TODAY(), "y"), " ") -> 25 | Y3: =IFERROR(DATEDIF(D3, E3, "D"), " ") -> 7 | Z3: {=_xlfn.IFS(Y3<=5, "On time", AND(Y3>5, Y3<>" "), "Delayed", Y3=" ", "pending" )} -> #NAME?
A4: ORD10003 | B4: C010 | C4: P101 | D4: 03/09/2025 | E4: 14/09/2025 | F4: pooja shah | G4: Female | H4: 16/09/1994 | I4: Bengaluru | J4: South | K4: Electronics | L4: Laptop | M4: 5 | N4: 55000 | O4: 5 | P4: 261250 | Q4: 3 | R4: NetBanking | S4: Aisha | T4: pooja.shah@company.com | U4: 9380975626 | V4: Pending | W4: =PROPER(TRIM(F4)) -> Pooja Shah | X4: =IFERROR(DATEDIF(H4, TODAY(), "y"), " ") -> 31 | Y4: =IFERROR(DATEDIF(D4, E4, "D"), " ") -> 11 | Z4: {=_xlfn.IFS(Y4<=5, "On time", AND(Y4>5, Y4<>" "), "Delayed", Y4=" ", "pending" )} -> #NAME?
A5: ORD10002 | B5: C008 | C5: P202 | D5: 21/03/2026 | E5: 02/04/2026 | F5: Kavya Nair | G5: Female | H5: 07/03/2004 | I5: Bengaluru | J5: South | K5: Home Appliances | L5: Iron | M5: 5 | N5: 2200 | O5: 5 | P5: 10450 | Q5: 5 | R5: NetBanking | S5: Aisha | T5: kavya.nair@company.com | U5: 9600261125 | V5: Cancelled | W5: =PROPER(TRIM(F5)) -> Kavya Nair | X5: =IFERROR(DATEDIF(H5, TODAY(), "y"), " ") -> 22 | Y5: =IFERROR(DATEDIF(D5, E5, "D"), " ") -> 12 | Z5: {=_xlfn.IFS(Y5<=5, "On time", AND(Y5>5, Y5<>" "), "Delayed", Y5=" ", "pending" )} -> #NAME?
A6: ORD10005 | B6: C009 | C6: P103 | D6: 27/09/2025 | E6: 07/10/2025 | F6: Mohit Verma | G6: Male | H6: 13/04/1976 | I6: Delhi | J6: North | K6: Electronics | L6: Keyboard | M6: 8 | N6: 1200 | O6: 5 | P6: 9120 | Q6: 2 | R6: Card | S6: Aisha | T6: mohit.verma@company.com | U6: 9724635978 | V6: Pending | W6: =PROPER(TRIM(F6)) -> Mohit Verma | X6: =IFERROR(DATEDIF(H6, TODAY(), "y"), " ") -> 50 | Y6: =IFERROR(DATEDIF(D6, E6, "D"), " ") -> 10 | Z6: {=_xlfn.IFS(Y6<=5, "On time", AND(Y6>5, Y6<>" "), "Delayed", Y6=" ", "pending" )} -> #NAME?
A7: ORD10006 | B7: C007 | C7: P202 | D7: 04/01/2026 | E7: 12/01/2026 | F7: arjun Rao | G7: Male | H7: 07/02/1988 | I7: Hyderabad | J7: South | K7: Home Appliances | L7: Iron | M7: 4 | N7: 2200 | O7: 0 | P7: 8800 | Q7: 1 | R7: UPI | S7: Ritika | T7: arjun.rao@company.com | U7: 9780584905 | V7: Completed | W7: =PROPER(TRIM(F7)) -> Arjun Rao | X7: =IFERROR(DATEDIF(H7, TODAY(), "y"), " ") -> 38 | Y7: =IFERROR(DATEDIF(D7, E7, "D"), " ") -> 8 | Z7: {=_xlfn.IFS(Y7<=5, "On time", AND(Y7>5, Y7<>" "), "Delayed", Y7=" ", "pending" )} -> #NAME?
A8: ORD10007 | B8: C008 | C8: P201 | D8: 31/02/2025 | E8: 25/02/2026 | F8: Kavya Nair | G8: Female | H8: 20/03/2003 | I8: Hyderabad | J8: South | K8: Home Appliances | L8: Mixer | M8: 2 | N8: 3500 | O8: 5 | P8: 6650 | Q8: 1 | R8: UPI | S8: Ritika | T8: kavya.nair@company.com | U8: 9958252176 | V8: Completed | W8: =PROPER(TRIM(F8)) -> Kavya Nair | X8: =IFERROR(DATEDIF(H8, TODAY(), "y"), " ") -> 23 | Y8: =IFERROR(DATEDIF(D8, E8, "D"), " ") | Z8: {=_xlfn.IFS(Y8<=5, "On time", AND(Y8>5, Y8<>" "), "Delayed", Y8=" ", "pending" )} -> #NAME?
A9: ORD10008 | B9: C002 | C9: P104 | D9: 13/04/2025 | E9: 19/04/2025 | F9: Priya Patel | G9: Female | H9: 07/03/1995 | I9: Mumbai | J9: West | K9: Electronics | L9: Monitor | M9: 14 | N9: 12000 | O9: 15 | P9: 142800 | Q9: 4 | R9: NetBanking | S9: Ritika | T9: priYa.patel@company.com | U9: 9705521654 | V9: Completed | W9: =PROPER(TRIM(F9)) -> Priya Patel | X9: =IFERROR(DATEDIF(H9, TODAY(), "y"), " ") -> 31 | Y9: =IFERROR(DATEDIF(D9, E9, "D"), " ") -> 6 | Z9: {=_xlfn.IFS(Y9<=5, "On time", AND(Y9>5, Y9<>" "), "Delayed", Y9=" ", "pending" )} -> #NAME?
A10: ORD10009 | B10: C008 | C10: P104 | D10: 31/01/2026 | E10: 02/02/2026 | F10: kavya Nair | G10: Female | H10: 06/04/1997 | I10: Pune | J10: West | K10: Electronics | L10: Monitor | M10: 4 | N10: 12000 | O10: 15 | P10: 40800 | Q10: 4 | R10: UPI | S10: Neha | T10: kavya.nair@company.com | U10: 9588041011 | V10: Completed | W10: =PROPER(TRIM(F10)) -> Kavya Nair | X10: =IFERROR(DATEDIF(H10, TODAY(), "y"), " ") -> 29 | Y10: =IFERROR(DATEDIF(D10, E10, "D"), " ") -> 2 | Z10: {=_xlfn.IFS(Y10<=5, "On time", AND(Y10>5, Y10<>" "), "Delayed", Y10=" ", "pending" )} -> #NAME?
A11: ORD10010 | B11: C002 | C11: P301 | D11: 25/03/2025 | E11: 27/03/2025 | F11: Priya Patel | G11: Female | H11: 07/01/1990 | I11: Mumbai | J11: West | K11: Stationery | L11: Notebook | M11: 6 | N11: 60 | O11: 0 | P11: 360 | Q11: 4 | R11: Card | S11: Neha | T11: PRiya.patel@company.com | U11: 9340540608 | V11: Completed | W11: =PROPER(TRIM(F11)) -> Priya Patel | X11: =IFERROR(DATEDIF(H11, TODAY(), "y"), " ") -> 36 | Y11: =IFERROR(DATEDIF(D11, E11, "D"), " ") -> 2 | Z11: {=_xlfn.IFS(Y11<=5, "On time", AND(Y11>5, Y11<>" "), "Delayed", Y11=" ", "pending" )} -> #NAME?
A12: ORD10011 | B12: C003 | C12: P202 | D12: 19/09/2025 | E12: 23/09/2025 | F12: Rohit Singh | G12: Male | H12: 10/05/1982 | I12: Delhi | J12: North | K12: Home Appliances | L12: Iron | M12: -3 | N12: 2200 | O12: 0 | P12: 35200 | Q12: 2 | R12: Card | S12: Rahul | T12: rohit.singh@company.com | U12: 9521710321 | V12: Pending | W12: =PROPER(TRIM(F12)) -> Rohit Singh | X12: =IFERROR(DATEDIF(H12, TODAY(), "y"), " ") -> 44 | Y12: =IFERROR(DATEDIF(D12, E12, "D"), " ") -> 4 | Z12: {=_xlfn.IFS(Y12<=5, "On time", AND(Y12>5, Y12<>" "), "Delayed", Y12=" ", "pending" )} -> #NAME?
A13: ORD10012 | B13: C008 | C13: P201 | D13: 08/03/2025 | E13: 15/03/2025 | F13: Kavya Nair | G13: Female | H13: 23/01/1982 | I13: Ahmedabad | J13: West | K13: Home Appliances | L13: Mixer | M13: 10 | N13: 3500 | O13: 5 | P13: 33250 | Q13: 5 | R13: Card | S13: Aisha | T13: kavya.nair@company.com | U13: 9123535241 | V13: Cancelled | W13: =PROPER(TRIM(F13)) -> Kavya Nair | X13: =IFERROR(DATEDIF(H13, TODAY(), "y"), " ") -> 44 | Y13: =IFERROR(DATEDIF(D13, E13, "D"), " ") -> 7 | Z13: {=_xlfn.IFS(Y13<=5, "On time", AND(Y13>5, Y13<>" "), "Delayed", Y13=" ", "pending" )} -> #NAME?
... A39: ORD10038 | B39: C006 | C39: P201 | D39: 08/03/2026 | E39: 20/03/2026 | F39: Sneha Joshi | G39: Female | H39: 21/06/1980 | I39: Delhi | J39: North | K39: Home Appliances | L39: Mixer | M39: 20 | N39: 3500 | O39: 10 | P39: 63000 | Q39: 3 | R39: Card | S39: Rahul | T39: sneha.joshi@company.com | U39: 9283578533 | V39: Cancelled | W39: =PROPER(TRIM(F39)) -> Sneha Joshi | X39: =IFERROR(DATEDIF(H39, TODAY(), "y"), " ") -> 46 | Y39: =IFERROR(DATEDIF(D39, E39, "D"), " ") -> 12 | Z39: {=_xlfn.IFS(Y39<=5, "On time", AND(Y39>5, Y39<>" "), "Delayed", Y39=" ", "pending" )} -> #NAME?
A40: ORD10039 | B40: C008 | C40: P302 | D40: 13/02/2025 | E40: 19/02/2025 | F40: Kavya Nair | G40: Female | H40: 17/06/1979 | I40: Pune | J40: West | K40: Stationery | L40: Pen | M40: 5 | N40: 1200 | O40: 0 | P40: 100 | Q40: 1 | R40: Cash | S40: Rahul | T40: kavya.nair@company.com | U40: 9963005771 | V40: Cancelled | W40: =PROPER(TRIM(F40)) -> Kavya Nair | X40: =IFERROR(DATEDIF(H40, TODAY(), "y"), " ") -> 47 | Y40: =IFERROR(DATEDIF(D40, E40, "D"), " ") -> 6 | Z40: {=_xlfn.IFS(Y40<=5, "On time", AND(Y40>5, Y40<>" "), "Delayed", Y40=" ", "pending" )} -> #NAME?
A41: ORD10040 | B41: C010 | C41: P203 | D41: 05/10/2025 | E41: 15/10/2025 | F41: Pooja Shah | G41: Female | H41: 18/06/1992 | I41: Mumbai | J41: West | K41: Home Appliances | L41: Microwave | M41: 20 | N41: 8500 | O41: 0 | P41: 170000 | Q41: 1 | R41: UPI | S41: Neha | T41: pooja.shah@company.com | U41: 9484632635 | V41: Cancelled | W41: =PROPER(TRIM(F41)) -> Pooja Shah | X41: =IFERROR(DATEDIF(H41, TODAY(), "y"), " ") -> 34 | Y41: =IFERROR(DATEDIF(D41, E41, "D"), " ") -> 10 | Z41: {=_xlfn.IFS(Y41<=5, "On time", AND(Y41>5, Y41<>" "), "Delayed", Y41=" ", "pending" )} -> #NAME?
A42: ORD10041 | B42: C007 | C42: P301 | D42: 10/02/2026 | E42: 12/02/2026 | F42: Arjun Rao | G42: Male | H42: 06/06/1994 | I42: Bengaluru | J42: South | K42: Stationery | L42: Notebook | M42: 8 | N42: 60 | O42: 15 | P42: 408 | Q42: 5 | R42: UPI | S42: Rahul | T42: arjun.rao@company.com | U42: 9276319484 | V42: Pending | W42: =PROPER(TRIM(F42)) -> Arjun Rao | X42: =IFERROR(DATEDIF(H42, TODAY(), "y"), " ") -> 32 | Y42: =IFERROR(DATEDIF(D42, E42, "D"), " ") -> 2 | Z42: {=_xlfn.IFS(Y42<=5, "On time", AND(Y42>5, Y42<>" "), "Delayed", Y42=" ", "pending" )} -> #NAME?
A43: ORD10042 | B43: C010 | C43: P201 | D43: 04/06/2025 | E43: 16/06/2025 | F43: Pooja Shah | G43: Female | H43: 22/09/1988 | I43: Pune | J43: West | K43: Home Appliances | L43: Mixer | M43: 8 | N43: 3500 | O43: 5 | P43: 26600 | Q43: 1 | R43: Card | S43: Neha | T43: pooja.shah@company.com | U43: 9619034852 | V43: Pending | W43: =PROPER(TRIM(F43)) -> Pooja Shah | X43: =IFERROR(DATEDIF(H43, TODAY(), "y"), " ") -> 37 | Y43: =IFERROR(DATEDIF(D43, E43, "D"), " ") -> 12 | Z43: {=_xlfn.IFS(Y43<=5, "On time", AND(Y43>5, Y43<>" "), "Delayed", Y43=" ", "pending" )} -> #NAME?
A44: ORD10043 | B44: C009 | C44: P203 | D44: 08/02/2026 | E44: 14/02/2026 | F44: Mohit Verma | G44: Male | H44: 14/07/2001 | I44: Jaipur | J44: North | K44: Home Appliances | L44: Microwave | M44: 1 | N44: 8500 | O44: 0 | P44: 8500 | Q44: 2 | R44: Card | S44: Neha | T44: mohit.verma@company.com | U44: 9636416962 | V44: Pending | W44: =PROPER(TRIM(F44)) -> Mohit Verma | X44: =IFERROR(DATEDIF(H44, TODAY(), "y"), " ") -> 25 | Y44: =IFERROR(DATEDIF(D44, E44, "D"), " ") -> 6 | Z44: {=_xlfn.IFS(Y44<=5, "On time", AND(Y44>5, Y44<>" "), "Delayed", Y44=" ", "pending" )} -> #NAME?
A45: ORD10044 | B45: C001 | C45: P303 | D45: 30/03/2025 | E45: 31/03/2025 | F45: amit Sharma | G45: Male | H45: 09/08/1991 | I45: Pune | J45: West | K45: Stationery | L45: Marker | M45: 8 | N45: 45 | O45: 15 | P45: 306 | Q45: 2 | R45: Card | S45: Aisha | T45: amit.sharma@company.com | U45: 9357133880 | V45: Completed | W45: =PROPER(TRIM(F45)) -> Amit Sharma | X45: =IFERROR(DATEDIF(H45, TODAY(), "y"), " ") -> 34 | Y45: =IFERROR(DATEDIF(D45, E45, "D"), " ") -> 1 | Z45: {=_xlfn.IFS(Y45<=5, "On time", AND(Y45>5, Y45<>" "), "Delayed", Y45=" ", "pending" )} -> #NAME?
A46: ORD10045 | B46: C006 | C46: P202 | D46: 25/04/2025 | E46: 28/04/2025 | F46: Sneha Joshi | G46: Female | H46: 21/10/1988 | I46: Pune | J46: West | K46: Home Appliances | L46: Iron | M46: 16 | N46: 2200 | O46: 5 | P46: 33440 | Q46: 5 | R46: Card | S46: Aisha | T46: sneha.joshi@company.com | U46: 9575210324 | V46: Cancelled | W46: =PROPER(TRIM(F46)) -> Sneha Joshi | X46: =IFERROR(DATEDIF(H46, TODAY(), "y"), " ") -> 37 | Y46: =IFERROR(DATEDIF(D46, E46, "D"), " ") -> 3 | Z46: {=_xlfn.IFS(Y46<=5, "On time", AND(Y46>5, Y46<>" "), "Delayed", Y46=" ", "pending" )} -> #NAME?
A47: ORD10046 | B47: C009 | C47: P201 | D47: 13/10/2025 | E47: 23/10/2025 | F47: Mohit Verma | G47: Male | H47: 19/11/2002 | I47: Bengaluru | J47: South | K47: Home Appliances | L47: Mixer | M47: 19 | N47: 3500 | O47: 20 | P47: 53200 | Q47: 3 | R47: Cash | S47: Karan | T47: mohit.verma@company.com | U47: 9276080204 | V47: Cancelled | W47: =PROPER(TRIM(F47)) -> Mohit Verma | X47: =IFERROR(DATEDIF(H47, TODAY(), "y"), " ") -> 23 | Y47: =IFERROR(DATEDIF(D47, E47, "D"), " ") -> 10 | Z47: {=_xlfn.IFS(Y47<=5, "On time", AND(Y47>5, Y47<>" "), "Delayed", Y47=" ", "pending" )} -> #NAME?
A48: ORD10047 | B48: C006 | C48: P102 | D48: 11/10/2025 | E48: 14/10/2025 | F48: Sneha Joshi | G48: Female | H48: 06/07/2000 | I48: Pune | J48: West | K48: Electronics | L48: Mouse | M48: 15 | N48: 700 | O48: 15 | P48: 8925 | Q48: 4 | R48: UPI | S48: Neha | T48: sneha.joshicompany.com | U48: 9856624471 | V48: Completed | W48: =PROPER(TRIM(F48)) -> Sneha Joshi | X48: =IFERROR(DATEDIF(H48, TODAY(), "y"), " ") -> 26 | Y48: =IFERROR(DATEDIF(D48, E48, "D"), " ") -> 3 | Z48: {=_xlfn.IFS(Y48<=5, "On time", AND(Y48>5, Y48<>" "), "Delayed", Y48=" ", "pending" )} -> #NAME?
A49: ORD10048 | B49: C006 | C49: P102 | D49: 27/11/2025 | E49: 03/12/2025 | F49: Sneha Joshi | G49: Female | H49: 26/11/1998 | I49: Jaipur | J49: North | K49: Electronics | L49: Mouse | M49: 19 | N49: 700 | O49: 20 | P49: 10640 | Q49: 1 | R49: Cash | S49: Neha | T49: sneha.joshi@company.com | U49: 9238141322 | V49: Completed | W49: =PROPER(TRIM(F49)) -> Sneha Joshi | X49: =IFERROR(DATEDIF(H49, TODAY(), "y"), " ") -> 27 | Y49: =IFERROR(DATEDIF(D49, E49, "D"), " ") -> 6 | Z49: {=_xlfn.IFS(Y49<=5, "On time", AND(Y49>5, Y49<>" "), "Delayed", Y49=" ", "pending" )} -> #NAME?
A50: ORD10049 | B50: C009 | C50: P104 | D50: 19/04/2026 | F50: Mohit Verma | G50: Male | H50: 03/06/1996 | I50: Delhi | J50: North | K50: Electronics | L50: Monitor | M50: 19 | N50: 12000 | O50: 0 | P50: 228000 | Q50: 1 | R50: NetBanking | S50: Aisha | T50: mohit.verma@company.com | U50: 9890380030 | V50: Completed | W50: =PROPER(TRIM(F50)) -> Mohit Verma | X50: =IFERROR(DATEDIF(H50, TODAY(), "y"), " ") -> 30 | Y50: =IFERROR(DATEDIF(D50, E50, "D"), " ") | Z50: {=_xlfn.IFS(Y50<=5, "On time", AND(Y50>5, Y50<>" "), "Delayed", Y50=" ", "pending" )} -> #NAME?
A51: ORD10050 | B51: C004 | C51: P103 | D51: 19/04/2026 | E51: 21/04/2026 | F51: Anita Gupta | G51: Female | H51: 15/03/1987 | I51: Pune | J51: West | K51: Electronics | L51: Keyboard | M51: 6 | N51: 1200 | O51: 5 | P51: 6840 | Q51: 2 | R51: Cash | S51: Ritika | T51: anita.gupta@company.com | U51: 9495893170 | V51: Pending | W51: =PROPER(TRIM(F51)) -> Anita Gupta | X51: =IFERROR(DATEDIF(H51, TODAY(), "y"), " ") -> 39 | Y51: =IFERROR(DATEDIF(D51, E51, "D"), " ") -> 2 | Z51: {=_xlfn.IFS(Y51<=5, "On time", AND(Y51>5, Y51<>" "), "Delayed", Y51=" ", "pending" )} -> #NAME?
A52: ORD10051 | B52: C010 | C52: P202 | D52: 28/03/2025 | E52: 07/04/2025 | F52: POoja Shah | G52: Female | H52: 20/02/1979 | I52: Bengaluru | J52: South | K52: Home Appliances | L52: Iron | M52: 7 | N52: 2200 | O52: 15 | P52: 13090 | Q52: 1 | R52: UPI | S52: Aisha | T52: pooja.shah@company.com | U52: 9485166307 | V52: Completed | W52: =PROPER(TRIM(F52)) -> Pooja Shah | X52: =IFERROR(DATEDIF(H52, TODAY(), "y"), " ") -> 47 | Y52: =IFERROR(DATEDIF(D52, E52, "D"), " ") -> 10 | Z52: {=_xlfn.IFS(Y52<=5, "On time", AND(Y52>5, Y52<>" "), "Delayed", Y52=" ", "pending" )} -> #NAME?
A53: ORD10052 | B53: C002 | C53: P301 | D53: 25/08/2025 | E53: 28/08/2025 | F53: Priya Patel | G53: Female | H53: 09/08/2000 | I53: Jaipur | J53: North | K53: Stationery | L53: Notebook | M53: 8 | N53: 60 | O53: 10 | P53: 432 | Q53: 5 | R53: Card | S53: Aisha | T53: priya.patel@company.com | U53: 9924709648 | V53: Cancelled | W53: =PROPER(TRIM(F53)) -> Priya Patel | X53: =IFERROR(DATEDIF(H53, TODAY(), "y"), " ") -> 25 | Y53: =IFERROR(DATEDIF(D53, E53, "D"), " ") -> 3 | Z53: {=_xlfn.IFS(Y53<=5, "On time", AND(Y53>5, Y53<>" "), "Delayed", Y53=" ", "pending" )} -> #NAME?
A54: ORD10053 | B54: C005 | C54: P101 | D54: 19/08/2025 | E54: 23/08/2025 | F54: Vikas Mehta | G54: Male | H54: 17/01/1976 | I54: Kolkata | J54: East | K54: Electronics | L54: Laptop | M54: 12 | N54: 55000 | O54: 5 | P54: 627000 | Q54: 2 | R54: UPI | S54: Rahul | T54: vikas.mehta@company.com | U54: 9350554626 | V54: Pending | W54: =PROPER(TRIM(F54)) -> Vikas Mehta | X54: =IFERROR(DATEDIF(H54, TODAY(), "y"), " ") -> 50 | Y54: =IFERROR(DATEDIF(D54, E54, "D"), " ") -> 4 | Z54: {=_xlfn.IFS(Y54<=5, "On time", AND(Y54>5, Y54<>" "), "Delayed", Y54=" ", "pending" )} -> #NAME?
A55: ORD10054 | B55: C008 | C55: P102 | D55: 27/07/2025 | E55: 05/08/2025 | F55: Kavya Nair | G55: Female | H55: 04/04/1975 | I55: Jaipur | J55: North | K55: Electronics | L55: Mouse | M55: 3 | N55: 700 | O55: 0 | P55: 2100 | Q55: 3 | R55: Card | S55: Karan | T55: kavya.nair@company.com | U55: 9743295580 | V55: Cancelled | W55: =PROPER(TRIM(F55)) -> Kavya Nair | X55: =IFERROR(DATEDIF(H55, TODAY(), "y"), " ") -> 51 | Y55: =IFERROR(DATEDIF(D55, E55, "D"), " ") -> 9 | Z55: {=_xlfn.IFS(Y55<=5, "On time", AND(Y55>5, Y55<>" "), "Delayed", Y55=" ", "pending" )} -> #NAME?
A56: ORD10055 | B56: C003 | C56: P301 | D56: 21/02/2025 | E56: 26/02/2025 | F56: RoHit Singh | G56: Male | H56: 11/12/1976 | I56: Ahmedabad | J56: West | K56: Stationery | L56: Notebook | M56: 19 | N56: 60 | O56: 15 | P56: 969 | Q56: 4 | R56: Card | S56: Rahul | T56: rohit.singh@company.com | U56: 9822926495 | V56: Cancelled | W56: =PROPER(TRIM(F56)) -> Rohit Singh | X56: =IFERROR(DATEDIF(H56, TODAY(), "y"), " ") -> 49 | Y56: =IFERROR(DATEDIF(D56, E56, "D"), " ") -> 5 | Z56: {=_xlfn.IFS(Y56<=5, "On time", AND(Y56>5, Y56<>" "), "Delayed", Y56=" ", "pending" )} -> #NAME?
A57: ORD10056 | B57: C001 | C57: P301 | D57: 10/08/2025 | E57: 11/08/2025 | F57: Amit Sharma | G57: Male | H57: 03/12/1979 | I57: Jaipur | J57: North | K57: Stationery | L57: Notebook | M57: 9 | N57: 60 | O57: 20 | P57: 432 | Q57: 1 | R57: NetBanking | S57: Neha | T57: amit.sharma@company.com | U57: 9518298190 | V57: Pending | W57: =PROPER(TRIM(F57)) -> Amit Sharma | X57: =IFERROR(DATEDIF(H57, TODAY(), "y"), " ") -> 46 | Y57: =IFERROR(DATEDIF(D57, E57, "D"), " ") -> 1 | Z57: {=_xlfn.IFS(Y57<=5, "On time", AND(Y57>5, Y57<>" "), "Delayed", Y57=" ", "pending" )} -> #NAME?
A58: ORD10057 | B58: C001 | C58: P102 | D58: 24/03/2026 | E58: 30/03/2026 | F58: Amit Sharma | G58: Male | H58: 27/12/1978 | I58: Bengaluru | J58: South | K58: Electronics | L58: Mouse | M58: 6 | N58: 700 | O58: 0 | P58: 4200 | Q58: 4 | R58: UPI | S58: Rahul | T58: amit.sharmcompany.com | U58: 9366223547 | V58: Cancelled | W58: =PROPER(TRIM(F58)) -> Amit Sharma | X58: =IFERROR(DATEDIF(H58, TODAY(), "y"), " ") -> 47 | Y58: =IFERROR(DATEDIF(D58, E58, "D"), " ") -> 6 | Z58: {=_xlfn.IFS(Y58<=5, "On time", AND(Y58>5, Y58<>" "), "Delayed", Y58=" ", "pending" )} -> #NAME?
A59: ORD10058 | B59: C003 | C59: P303 | D59: 13/03/2026 | E59: 19/03/2026 | F59: Rohit Singh | G59: Male | H59: 15/04/1975 | I59: Delhi | J59: North | K59: Stationery | L59: Marker | M59: 18 | N59: 45 | O59: 5 | P59: 769.5 | Q59: 1 | R59: Card | S59: Aisha | T59: rohit.singh@company.com | U59: 9701988524 | V59: Pending | W59: =PROPER(TRIM(F59)) -> Rohit Singh | X59: =IFERROR(DATEDIF(H59, TODAY(), "y"), " ") -> 51 | Y59: =IFERROR(DATEDIF(D59, E59, "D"), " ") -> 6 | Z59: {=_xlfn.IFS(Y59<=5, "On time", AND(Y59>5, Y59<>" "), "Delayed", Y59=" ", "pending" )} -> #NAME?
A60: ORD10059 | B60: C007 | C60: P302 | D60: 15/06/2025 | E60: 26/06/2025 | F60: Arjun Rao | G60: Male | H60: 19/12/1988 | I60: Jaipur | J60: North | K60: Stationery | L60: Pen | M60: 8 | N60: 20 | O60: 5 | P60: 152 | Q60: 1 | R60: Card | S60: Ritika | T60: arjun.rao@company.com | U60: 9836327649 | V60: completed | W60: =PROPER(TRIM(F60)) -> Arjun Rao | X60: =IFERROR(DATEDIF(H60, TODAY(), "y"), " ") -> 37 | Y60: =IFERROR(DATEDIF(D60, E60, "D"), " ") -> 11 | Z60: {=_xlfn.IFS(Y60<=5, "On time", AND(Y60>5, Y60<>" "), "Delayed", Y60=" ", "pending" )} -> #NAME?
A61: ORD10060 | B61: C005 | C61: P102 | D61: 05/03/2025 | E61: 06/03/2025 | F61: Vikas Mehta | G61: Male | H61: 07/03/1979 | I61: Jaipur | J61: North | K61: Electronics | L61: Mouse | M61: 8 | N61: 700 | O61: 10 | P61: 5040 | Q61: 1 | R61: NetBanking | S61: Aisha | T61: Vikas.mehta@company.com | U61: 9261800516 | V61: Cancelled | W61: =PROPER(TRIM(F61)) -> Vikas Mehta | X61: =IFERROR(DATEDIF(H61, TODAY(), "y"), " ") -> 47 | Y61: =IFERROR(DATEDIF(D61, E61, "D"), " ") -> 1 | Z61: {=_xlfn.IFS(Y61<=5, "On time", AND(Y61>5, Y61<>" "), "Delayed", Y61=" ", "pending" )} -> #NAME?
A62: ORD10061 | B62: C008 | C62: P302 | D62: 09/04/2026 | E62: 19/04/2026 | F62: Kavya Nair | G62: Female | H62: 17/12/2003 | I62: Delhi | J62: North | K62: Stationery | L62: Pen | M62: 7 | N62: 20 | O62: 15 | P62: 119 | Q62: 5 | R62: Card | S62: Rahul | T62: kavya.nair@company.com | U62: 9950802015 | V62: Completed | W62: =PROPER(TRIM(F62)) -> Kavya Nair | X62: =IFERROR(DATEDIF(H62, TODAY(), "y"), " ") -> 22 | Y62: =IFERROR(DATEDIF(D62, E62, "D"), " ") -> 10 | Z62: {=_xlfn.IFS(Y62<=5, "On time", AND(Y62>5, Y62<>" "), "Delayed", Y62=" ", "pending" )} -> #NAME?
... A74: ORD10073 | B74: C008 | C74: P103 | D74: 13/12/2025 | E74: 23/12/2025 | F74: Kavya Nair | G74: Female | H74: 22/09/1981 | I74: Jaipur | J74: North | K74: Electronics | L74: Keyboard | M74: 1 | N74: 1200 | O74: 5 | P74: 1140 | Q74: 3 | R74: UPI | S74: Aisha | T74: kavya.nair@company.com | U74: 9808988530 | V74: Cancelled | W74: =PROPER(TRIM(F74)) -> Kavya Nair | X74: =IFERROR(DATEDIF(H74, TODAY(), "y"), " ") -> 44 | Y74: =IFERROR(DATEDIF(D74, E74, "D"), " ") -> 10 | Z74: {=_xlfn.IFS(Y74<=5, "On time", AND(Y74>5, Y74<>" "), "Delayed", Y74=" ", "pending" )} -> #NAME?
A75: ORD10074 | B75: C010 | C75: P202 | D75: 04/02/2026 | E75: 16/02/2026 | F75: Pooja Shah | G75: Female | H75: 20/06/1980 | J75: South | K75: Home Appliances | L75: Iron | M75: 1 | N75: 2200 | O75: 15 | P75: 1870 | Q75: 4 | R75: Card | S75: Aisha | T75: pooja.shah@company.com | U75: 9286410494 | V75: Completed | W75: =PROPER(TRIM(F75)) -> Pooja Shah | X75: =IFERROR(DATEDIF(H75, TODAY(), "y"), " ") -> 46 | Y75: =IFERROR(DATEDIF(D75, E75, "D"), " ") -> 12 | Z75: {=_xlfn.IFS(Y75<=5, "On time", AND(Y75>5, Y75<>" "), "Delayed", Y75=" ", "pending" )} -> #NAME?
A76: ORD10075 | B76: C003 | C76: P103 | D76: 26/01/2026 | E76: 28/01/2026 | F76: Rohit Singh | G76: Male | H76: 02/11/1982 | I76: Pune | J76: West | K76: Electronics | L76: Keyboard | M76: 3 | N76: 1200 | O76: 10 | P76: 3240 | Q76: 5 | R76: Cash | S76: Rahul | T76: rohit.singh@company.com | U76: 9311555196 | V76: Completed | W76: =PROPER(TRIM(F76)) -> Rohit Singh | X76: =IFERROR(DATEDIF(H76, TODAY(), "y"), " ") -> 43 | Y76: =IFERROR(DATEDIF(D76, E76, "D"), " ") -> 2 | Z76: {=_xlfn.IFS(Y76<=5, "On time", AND(Y76>5, Y76<>" "), "Delayed", Y76=" ", "pending" )} -> #NAME?
...

Sheet Q4)Product_lookup_report
A1: Order_ID | B1: Customer_ID | C1: Product_ID | D1: Order_Date | E1: Delivery_Date | F1: Customer_Name | G1: Gender | H1: DOB | I1: City | J1: Region | K1: Category | L1: Product_Name | M1: Quantity | N1: Unit_Price | O1: Discount_% | P1: Sales | Q1: Rating | R1: Payment_Mode | S1: Salesperson | T1: Email | U1: Phone | V1: Order_Status | W1: Product_ID | X1: Product_ID | Y1: Category | Z1: Supplier | AA1: Cost_price | AB1: Warranty
A2: ORD10001 | B2: C008 | C2: P202 | D2: 18/09/2025 | E2: 22/09/2025 | F2: Kavya Nair | G2: Female | H2: 01/08/1976 | I2: Hyderabad | J2: South | K2: Home Appliances | L2: Iron | M2: 4 | N2: 2200 | O2: 10 | P2: 7920 | Q2: 4 | R2: Cash | S2: Ritika | T2: KAvya.nair@company.com | U2: 9431429797 | V2: Completed | W2: =C2 -> P202 | X2: {=_xlfn.XLOOKUP(C2,C:C, _xlfn.HSTACK(L:L,K:K,S:S,Product_master!E:E,Product_master!F:F))} -> #NAME? | Y2: #NAME? | Z2: #NAME? | AA2: #NAME? | AB2: #NAME?
A3: ORD10002 | B3: C008 | C3: P104 | D3: 27/04/2025 | E3: 04/05/2025 | F3: Kavya Nair | G3: Female | H3: 16/10/2000 | I3: Delhi | J3: North | K3: Electronics | L3: Monitor | M3: 17 | N3: 12000 | O3: 10 | P3: 183600 | Q3: 1 | R3: NetBanking | S3: Rahul | T3: kavya.nair@company.com | U3: 9129865339 | V3: Completed | W3: =C3 -> P104 | X3: {=_xlfn.XLOOKUP(C3,C:C, _xlfn.HSTACK(L:L,K:K,S:S,Product_master!E:E,Product_master!F:F ))} -> #NAME? | Y3: #NAME? | Z3: #NAME? | AA3: #NAME? | AB3: #NAME?
A4: ORD10003 | B4: C010 | C4: P101 | D4: 03/09/2025 | E4: 14/09/2025 | F4: pooja shah | G4: Female | H4: 16/09/1994 | I4: Bengaluru | J4: South | K4: Electronics | L4: Laptop | M4: 5 | N4: 55000 | O4: 5 | P4: 261250 | Q4: 3 | R4: NetBanking | S4: Aisha | T4: pooja.shah@company.com | U4: 9380975626 | V4: Pending | W4: =C4 -> P101 | X4: {=_xlfn.XLOOKUP(C4,C:C, _xlfn.HSTACK(L:L,K:K,S:S,Product_master!E:E,Product_master!F:F ))} -> #NAME? | Y4: #NAME? | Z4: #NAME? | AA4: #NAME? | AB4: #NAME?
A5: ORD10002 | B5: C008 | C5: P202 | D5: 21/03/2026 | E5: 02/04/2026 | F5: Kavya Nair | G5: Female | H5: 07/03/2004 | I5: Bengaluru | J5: South | K5: Home Appliances | L5: Iron | M5: 5 | N5: 2200 | O5: 5 | P5: 10450 | Q5: 5 | R5: NetBanking | S5: Aisha | T5: kavya.nair@company.com | U5: 9600261125 | V5: Cancelled | W5: =C5 -> P202 | X5: {=_xlfn.XLOOKUP(C5,C:C, _xlfn.HSTACK(L:L,K:K,S:S,Product_master!E:E,Product_master!F:F ))} -> #NAME? | Y5: #NAME? | Z5: #NAME? | AA5: #NAME? | AB5: #NAME?
A6: ORD10005 | B6: C009 | C6: P103 | D6: 27/09/2025 | E6: 07/10/2025 | F6: Mohit Verma | G6: Male | H6: 13/04/1976 | I6: Delhi | J6: North | K6: Electronics | L6: Keyboard | M6: 8 | N6: 1200 | O6: 5 | P6: 9120 | Q6: 2 | R6: Card | S6: Aisha | T6: mohit.verma@company.com | U6: 9724635978 | V6: Pending | W6: =C6 -> P103 | X6: {=_xlfn.XLOOKUP(C6,C:C, _xlfn.HSTACK(L:L,K:K,S:S,Product_master!E:E,Product_master!F:F ))} -> #NAME? | Y6: #NAME? | Z6: #NAME? | AA6: #NAME? | AB6: #NAME?
A7: ORD10006 | B7: C007 | C7: P202 | D7: 04/01/2026 | E7: 12/01/2026 | F7: arjun Rao | G7: Male | H7: 07/02/1988 | I7: Hyderabad | J7: South | K7: Home Appliances | L7: Iron | M7: 4 | N7: 2200 | O7: 0 | P7: 8800 | Q7: 1 | R7: UPI | S7: Ritika | T7: arjun.rao@company.com | U7: 9780584905 | V7: Completed | W7: =C7 -> P202 | X7: {=_xlfn.XLOOKUP(C7,C:C, _xlfn.HSTACK(L:L,K:K,S:S,Product_master!E:E,Product_master!F:F ))} -> #NAME? | Y7: #NAME? | Z7: #NAME? | AA7: #NAME? | AB7: #NAME?
A8: ORD10007 | B8: C008 | C8: P201 | D8: 31/02/2025 | E8: 25/02/2026 | F8: Kavya Nair | G8: Female | H8: 20/03/2003 | I8: Hyderabad | J8: South | K8: Home Appliances | L8: Mixer | M8: 2 | N8: 3500 | O8: 5 | P8: 6650 | Q8: 1 | R8: UPI | S8: Ritika | T8: kavya.nair@company.com | U8: 9958252176 | V8: Completed | W8: =C8 -> P201 | X8: {=_xlfn.XLOOKUP(C8,C:C, _xlfn.HSTACK(L:L,K:K,S:S,Product_master!E:E,Product_master!F:F ))} -> #NAME? | Y8: #NAME? | Z8: #NAME? | AA8: #NAME? | AB8: #NAME?
A9: ORD10008 | B9: C002 | C9: P104 | D9: 13/04/2025 | E9: 19/04/2025 | F9: Priya Patel | G9: Female | H9: 07/03/1995 | I9: Mumbai | J9: West | K9: Electronics | L9: Monitor | M9: 14 | N9: 12000 | O9: 15 | P9: 142800 | Q9: 4 | R9: NetBanking | S9: Ritika | T9: priYa.patel@company.com | U9: 9705521654 | V9: Completed | W9: =C9 -> P104 | X9: {=_xlfn.XLOOKUP(C9,C:C, _xlfn.HSTACK(L:L,K:K,S:S,Product_master!E:E,Product_master!F:F ))} -> #NAME? | Y9: #NAME? | Z9: #NAME? | AA9: #NAME? | AB9: #NAME?
A10: ORD10009 | B10: C008 | C10: P104 | D10: 31/01/2026 | E10: 02/02/2026 | F10: kavya Nair | G10: Female | H10: 06/04/1997 | I10: Pune | J10: West | K10: Electronics | L10: Monitor | M10: 4 | N10: 12000 | O10: 15 | P10: 40800 | Q10: 4 | R10: UPI | S10: Neha | T10: kavya.nair@company.com | U10: 9588041011 | V10: Completed | W10: =C10 -> P104 | X10: {=_xlfn.XLOOKUP(C10,C:C, _xlfn.HSTACK(L:L,K:K,S:S,Product_master!E:E,Product_master!F:F ))} -> #NAME? | Y10: #NAME? | Z10: #NAME? | AA10: #NAME? | AB10: #NAME?
A11: ORD10010 | B11: C002 | C11: P301 | D11: 25/03/2025 | E11: 27/03/2025 | F11: Priya Patel | G11: Female | H11: 07/01/1990 | I11: Mumbai | J11: West | K11: Stationery | L11: Notebook | M11: 6 | N11: 60 | O11: 0 | P11: 360 | Q11: 4 | R11: Card | S11: Neha | T11: PRiya.patel@company.com | U11: 9340540608 | V11: Completed | W11: =C11 -> P301 | X11: {=_xlfn.XLOOKUP(C11,C:C, _xlfn.HSTACK(L:L,K:K,S:S,Product_master!E:E,Product_master!F:F ))} -> #NAME? | Y11: #NAME? | Z11: #NAME? | AA11: #NAME? | AB11: #NAME?
A12: ORD10011 | B12: C003 | C12: P202 | D12: 19/09/2025 | E12: 23/09/2025 | F12: Rohit Singh | G12: Male | H12: 10/05/1982 | I12: Delhi | J12: North | K12: Home Appliances | L12: Iron | M12: -3 | N12: 2200 | O12: 0 | P12: 35200 | Q12: 2 | R12: Card | S12: Rahul | T12: rohit.singh@company.com | U12: 9521710321 | V12: Pending | W12: =C12 -> P202 | X12: {=_xlfn.XLOOKUP(C12,C:C, _xlfn.HSTACK(L:L,K:K,S:S,Product_master!E:E,Product_master!F:F ))} -> #NAME? | Y12: #NAME? | Z12: #NAME? | AA12: #NAME? | AB12: #NAME?
